Workbook

Sheet Seguridad
A2: SEGURIDAD · CONTROL DE FLOTA
A3: F&M Maquinarias | Datos piloto históricos + entrada de telemetría para estado actual
A4: Flota | D4: Turno | G4: Desde | I4: Hasta | L4: Unidad | N4: Vigencia (min)
B5: Volquete | E5: Ambos | H5: 46276 | J5: 46291 | M5: Todas | O5: 10
A6: Edita los filtros amarillos. La lectura actual requiere actualizar Telemetría; «sin lectura» no equivale a stand by.
A7: Filtros con listas: Flota, Turno y Unidad. Desde/Hasta acotan los datos; Vigencia define cuándo caduca una lectura.
A8: Eventos de sobrevelocidad | D8: Alertas de cinturón | G8: Salidas de geocerca | J8: Volquetes con lectura vigente
A9: =SUMIFS(Datos!$H$5:$H$228,Datos!$M$5:$M$228,1) -> 76 | D9: =SUMIFS(Datos!$I$5:$I$228,Datos!$M$5:$M$228,1) -> 8 | G9: =SUMIFS(Datos!$J$5:$J$228,Datos!$M$5:$M$228,1) -> 6 | J9: =COUNTIFS($C$18:$C$25,"Volquete",$H$18:$H$25,"En movimiento")+COUNTIFS($C$18:$C$25,"Volquete",$H$18:$H$25,"Stand by") -> 0
A11: Volquetes en movimiento | D11: Volquetes stand by | G11: Volquetes sin lectura vigente | J11: Última lectura de la flota
A12: =COUNTIFS($C$18:$C$25,"Volquete",$H$18:$H$25,"En movimiento") -> 0 | D12: =COUNTIFS($C$18:$C$25,"Volquete",$H$18:$H$25,"Stand by") -> 0 | G12: =COUNTIFS($C$18:$C$25,"Volquete",$H$18:$H$25,"Sin lectura vigente") -> 4 | J12: =IF(COUNT($D$18:$D$25)=0,"Sin telemetría",MAX($D$18:$D$25)) -> Sin telemetría
A15: ESTADO ACTUAL · ÚLTIMA LECTURA VIGENTE POR UNIDAD
A17: Unidad | B17: Filtro | C17: Tipo | D17: Última lectura | E17: Vel. GPS km/h | F17: Motor | G17: Edad min | H17: Estado | I17: Muestras | J17: Origen
A18: VOL-01 | B18: =IF(AND(OR($B$5="Todas",$B$5=C18),OR($M$5="Todas",$M$5=A18)),"Incluido","Fuera del filtro") -> Incluido | C18: Volquete | D18: =IF(B18="Fuera del filtro","",IF(COUNTIFS(Telemetría!$B$5:$B$504,A18,Telemetría!$A$5:$A$504,">="&$H$5,Telemetría!$A$5:$A$504,"<"&($J$5+1),Telemetría!$D$5:$D$504,IF($E$5="Ambos","*",$E$5))=0,"",_xlfn.MAXIFS(Telemetría!$A$5:$A$504,Telemetría!$B$5:$B$504,A18,Telemetría!$A$5:$A$504,">="&$H$5,Telemetría!$A$5:$A$504,"<"&($J$5+1),Telemetría!$D$5:$D$504,IF($E$5="Ambos","*",$E$5)))) | E18: =IF(I18=0,"",SUMIFS(Telemetría!$E$5:$E$504,Telemetría!$B$5:$B$504,A18,Telemetría!$A$5:$A$504,D18)) | F18: =IF(I18=0,"",SUMIFS(Telemetría!$F$5:$F$504,Telemetría!$B$5:$B$504,A18,Telemetría!$A$5:$A$504,D18)) | G18: =IF(D18="","",MAX(0,(NOW()-D18)*1440)) | H18: =IF(B18="Fuera del filtro","Fuera del filtro",IF(OR(D18="",G18>$O$5,I18<>1),"Sin lectura vigente",IF(E18>=1,"En movimiento",IF(F18=1,"Stand by","Detenido / motor apagado")))) -> Sin lectura vigente | I18: =IF(D18="",0,COUNTIFS(Telemetría!$B$5:$B$504,A18,Telemetría!$A$5:$A$504,D18)) -> 0 | J18: =IF(I18=0,"", "Telemetría")
A19: VOL-02 | B19: =IF(AND(OR($B$5="Todas",$B$5=C19),OR($M$5="Todas",$M$5=A19)),"Incluido","Fuera del filtro") -> Incluido | C19: Volquete | D19: =IF(B19="Fuera del filtro","",IF(COUNTIFS(Telemetría!$B$5:$B$504,A19,Telemetría!$A$5:$A$504,">="&$H$5,Telemetría!$A$5:$A$504,"<"&($J$5+1),Telemetría!$D$5:$D$504,IF($E$5="Ambos","*",$E$5))=0,"",_xlfn.MAXIFS(Telemetría!$A$5:$A$504,Telemetría!$B$5:$B$504,A19,Telemetría!$A$5:$A$504,">="&$H$5,Telemetría!$A$5:$A$504,"<"&($J$5+1),Telemetría!$D$5:$D$504,IF($E$5="Ambos","*",$E$5)))) | E19: =IF(I19=0,"",SUMIFS(Telemetría!$E$5:$E$504,Telemetría!$B$5:$B$504,A19,Telemetría!$A$5:$A$504,D19)) | F19: =IF(I19=0,"",SUMIFS(Telemetría!$F$5:$F$504,Telemetría!$B$5:$B$504,A19,Telemetría!$A$5:$A$504,D19)) | G19: =IF(D19="","",MAX(0,(NOW()-D19)*1440)) | H19: =IF(B19="Fuera del filtro","Fuera del filtro",IF(OR(D19="",G19>$O$5,I19<>1),"Sin lectura vigente",IF(E19>=1,"En movimiento",IF(F19=1,"Stand by","Detenido / motor apagado")))) -> Sin lectura vigente | I19: =IF(D19="",0,COUNTIFS(Telemetría!$B$5:$B$504,A19,Telemetría!$A$5:$A$504,D19)) -> 0 | J19: =IF(I19=0,"", "Telemetría")
A20: VOL-03 | B20: =IF(AND(OR($B$5="Todas",$B$5=C20),OR($M$5="Todas",$M$5=A20)),"Incluido","Fuera del filtro") -> Incluido | C20: Volquete | D20: =IF(B20="Fuera del filtro","",IF(COUNTIFS(Telemetría!$B$5:$B$504,A20,Telemetría!$A$5:$A$504,">="&$H$5,Telemetría!$A$5:$A$504,"<"&($J$5+1),Telemetría!$D$5:$D$504,IF($E$5="Ambos","*",$E$5))=0,"",_xlfn.MAXIFS(Telemetría!$A$5:$A$504,Telemetría!$B$5:$B$504,A20,Telemetría!$A$5:$A$504,">="&$H$5,Telemetría!$A$5:$A$504,"<"&($J$5+1),Telemetría!$D$5:$D$504,IF($E$5="Ambos","*",$E$5)))) | E20: =IF(I20=0,"",SUMIFS(Telemetría!$E$5:$E$504,Telemetría!$B$5:$B$504,A20,Telemetría!$A$5:$A$504,D20)) | F20: =IF(I20=0,"",SUMIFS(Telemetría!$F$5:$F$504,Telemetría!$B$5:$B$504,A20,Telemetría!$A$5:$A$504,D20)) | G20: =IF(D20="","",MAX(0,(NOW()-D20)*1440)) | H20: =IF(B20="Fuera del filtro","Fuera del filtro",IF(OR(D20="",G20>$O$5,I20<>1),"Sin lectura vigente",IF(E20>=1,"En movimiento",IF(F20=1,"Stand by","Detenido / motor apagado")))) -> Sin lectura vigente | I20: =IF(D20="",0,COUNTIFS(Telemetría!$B$5:$B$504,A20,Telemetría!$A$5:$A$504,D20)) -> 0 | J20: =IF(I20=0,"", "Telemetría")
A21: VOL-04 | B21: =IF(AND(OR($B$5="Todas",$B$5=C21),OR($M$5="Todas",$M$5=A21)),"Incluido","Fuera del filtro") -> Incluido | C21: Volquete | D21: =IF(B21="Fuera del filtro","",IF(COUNTIFS(Telemetría!$B$5:$B$504,A21,Telemetría!$A$5:$A$504,">="&$H$5,Telemetría!$A$5:$A$504,"<"&($J$5+1),Telemetría!$D$5:$D$504,IF($E$5="Ambos","*",$E$5))=0,"",_xlfn.MAXIFS(Telemetría!$A$5:$A$504,Telemetría!$B$5:$B$504,A21,Telemetría!$A$5:$A$504,">="&$H$5,Telemetría!$A$5:$A$504,"<"&($J$5+1),Telemetría!$D$5:$D$504,IF($E$5="Ambos","*",$E$5)))) | E21: =IF(I21=0,"",SUMIFS(Telemetría!$E$5:$E$504,Telemetría!$B$5:$B$504,A21,Telemetría!$A$5:$A$504,D21)) | F21: =IF(I21=0,"",SUMIFS(Telemetría!$F$5:$F$504,Telemetría!$B$5:$B$504,A21,Telemetría!$A$5:$A$504,D21)) | G21: =IF(D21="","",MAX(0,(NOW()-D21)*1440)) | H21: =IF(B21="Fuera del filtro","Fuera del filtro",IF(OR(D21="",G21>$O$5,I21<>1),"Sin lectura vigente",IF(E21>=1,"En movimiento",IF(F21=1,"Stand by","Detenido / motor apagado")))) -> Sin lectura vigente | I21: =IF(D21="",0,COUNTIFS(Telemetría!$B$5:$B$504,A21,Telemetría!$A$5:$A$504,D21)) -> 0 | J21: =IF(I21=0,"", "Telemetría")
A22: CAM-01 | B22: =IF(AND(OR($B$5="Todas",$B$5=C22),OR($M$5="Todas",$M$5=A22)),"Incluido","Fuera del filtro") -> Fuera del filtro | C22: Camioneta | D22: =IF(B22="Fuera del filtro","",IF(COUNTIFS(Telemetría!$B$5:$B$504,A22,Telemetría!$A$5:$A$504,">="&$H$5,Telemetría!$A$5:$A$504,"<"&($J$5+1),Telemetría!$D$5:$D$504,IF($E$5="Ambos","*",$E$5))=0,"",_xlfn.MAXIFS(Telemetría!$A$5:$A$504,Telemetría!$B$5:$B$504,A22,Telemetría!$A$5:$A$504,">="&$H$5,Telemetría!$A$5:$A$504,"<"&($J$5+1),Telemetría!$D$5:$D$504,IF($E$5="Ambos","*",$E$5)))) | E22: =IF(I22=0,"",SUMIFS(Telemetría!$E$5:$E$504,Telemetría!$B$5:$B$504,A22,Telemetría!$A$5:$A$504,D22)) | F22: =IF(I22=0,"",SUMIFS(Telemetría!$F$5:$F$504,Telemetría!$B$5:$B$504,A22,Telemetría!$A$5:$A$504,D22)) | G22: =IF(D22="","",MAX(0,(NOW()-D22)*1440)) | H22: =IF(B22="Fuera del filtro","Fuera del filtro",IF(OR(D22="",G22>$O$5,I22<>1),"Sin lectura vigente",IF(E22>=1,"En movimiento",IF(F22=1,"Stand by","Detenido / motor apagado")))) -> Fuera del filtro | I22: =IF(D22="",0,COUNTIFS(Telemetría!$B$5:$B$504,A22,Telemetría!$A$5:$A$504,D22)) -> 0 | J22: =IF(I22=0,"", "Telemetría")
A23: CAM-02 | B23: =IF(AND(OR($B$5="Todas",$B$5=C23),OR($M$5="Todas",$M$5=A23)),"Incluido","Fuera del filtro") -> Fuera del filtro | C23: Camioneta | D23: =IF(B23="Fuera del filtro","",IF(COUNTIFS(Telemetría!$B$5:$B$504,A23,Telemetría!$A$5:$A$504,">="&$H$5,Telemetría!$A$5:$A$504,"<"&($J$5+1),Telemetría!$D$5:$D$504,IF($E$5="Ambos","*",$E$5))=0,"",_xlfn.MAXIFS(Telemetría!$A$5:$A$504,Telemetría!$B$5:$B$504,A23,Telemetría!$A$5:$A$504,">="&$H$5,Telemetría!$A$5:$A$504,"<"&($J$5+1),Telemetría!$D$5:$D$504,IF($E$5="Ambos","*",$E$5)))) | E23: =IF(I23=0,"",SUMIFS(Telemetría!$E$5:$E$504,Telemetría!$B$5:$B$504,A23,Telemetría!$A$5:$A$504,D23)) | F23: =IF(I23=0,"",SUMIFS(Telemetría!$F$5:$F$504,Telemetría!$B$5:$B$504,A23,Telemetría!$A$5:$A$504,D23)) | G23: =IF(D23="","",MAX(0,(NOW()-D23)*1440)) | H23: =IF(B23="Fuera del filtro","Fuera del filtro",IF(OR(D23="",G23>$O$5,I23<>1),"Sin lectura vigente",IF(E23>=1,"En movimiento",IF(F23=1,"Stand by","Detenido / motor apagado")))) -> Fuera del filtro | I23: =IF(D23="",0,COUNTIFS(Telemetría!$B$5:$B$504,A23,Telemetría!$A$5:$A$504,D23)) -> 0 | J23: =IF(I23=0,"", "Telemetría")
A24: MIN-01 | B24: =IF(AND(OR($B$5="Todas",$B$5=C24),OR($M$5="Todas",$M$5=A24)),"Incluido","Fuera del filtro") -> Fuera del filtro | C24: Minibús | D24: =IF(B24="Fuera del filtro","",IF(COUNTIFS(Telemetría!$B$5:$B$504,A24,Telemetría!$A$5:$A$504,">="&$H$5,Telemetría!$A$5:$A$504,"<"&($J$5+1),Telemetría!$D$5:$D$504,IF($E$5="Ambos","*",$E$5))=0,"",_xlfn.MAXIFS(Telemetría!$A$5:$A$504,Telemetría!$B$5:$B$504,A24,Telemetría!$A$5:$A$504,">="&$H$5,Telemetría!$A$5:$A$504,"<"&($J$5+1),Telemetría!$D$5:$D$504,IF($E$5="Ambos","*",$E$5)))) | E24: =IF(I24=0,"",SUMIFS(Telemetría!$E$5:$E$504,Telemetría!$B$5:$B$504,A24,Telemetría!$A$5:$A$504,D24)) | F24: =IF(I24=0,"",SUMIFS(Telemetría!$F$5:$F$504,Telemetría!$B$5:$B$504,A24,Telemetría!$A$5:$A$504,D24)) | G24: =IF(D24="","",MAX(0,(NOW()-D24)*1440)) | H24: =IF(B24="Fuera del filtro","Fuera del filtro",IF(OR(D24="",G24>$O$5,I24<>1),"Sin lectura vigente",IF(E24>=1,"En movimiento",IF(F24=1,"Stand by","Detenido / motor apagado")))) -> Fuera del filtro | I24: =IF(D24="",0,COUNTIFS(Telemetría!$B$5:$B$504,A24,Telemetría!$A$5:$A$504,D24)) -> 0 | J24: =IF(I24=0,"", "Telemetría")
A25: COM-01 | B25: =IF(AND(OR($B$5="Todas",$B$5=C25),OR($M$5="Todas",$M$5=A25)),"Incluido","Fuera del filtro") -> Fuera del filtro | C25: Combi | D25: =IF(B25="Fuera del filtro","",IF(COUNTIFS(Telemetría!$B$5:$B$504,A25,Telemetría!$A$5:$A$504,">="&$H$5,Telemetría!$A$5:$A$504,"<"&($J$5+1),Telemetría!$D$5:$D$504,IF($E$5="Ambos","*",$E$5))=0,"",_xlfn.MAXIFS(Telemetría!$A$5:$A$504,Telemetría!$B$5:$B$504,A25,Telemetría!$A$5:$A$504,">="&$H$5,Telemetría!$A$5:$A$504,"<"&($J$5+1),Telemetría!$D$5:$D$504,IF($E$5="Ambos","*",$E$5)))) | E25: =IF(I25=0,"",SUMIFS(Telemetría!$E$5:$E$504,Telemetría!$B$5:$B$504,A25,Telemetría!$A$5:$A$504,D25)) | F25: =IF(I25=0,"",SUMIFS(Telemetría!$F$5:$F$504,Telemetría!$B$5:$B$504,A25,Telemetría!$A$5:$A$504,D25)) | G25: =IF(D25="","",MAX(0,(NOW()-D25)*1440)) | H25: =IF(B25="Fuera del filtro","Fuera del filtro",IF(OR(D25="",G25>$O$5,I25<>1),"Sin lectura vigente",IF(E25>=1,"En movimiento",IF(F25=1,"Stand by","Detenido / motor apagado")))) -> Fuera del filtro | I25: =IF(D25="",0,COUNTIFS(Telemetría!$B$5:$B$504,A25,Telemetría!$A$5:$A$504,D25)) -> 0 | J25: =IF(I25=0,"", "Telemetría")
A27: Criterio actual: movimiento ≥ 1 km/h; stand by = motor encendido y velocidad < 1 km/h; lectura vencida = sin estado verificable.
A28: «En tiempo real» depende de conexión y frecuencia de importación
A30: RESUMEN DIARIO · FLOTA FILTRADA
A32: Fecha | B32: km | C32: Movimiento h | D32: Media km/h | E32: Máxima GPS km/h | F32: Volquetes con movimiento | G32: Volquetes stand by* | H32: Eventos de sobrevelocidad
A33: =DATE(2026,9,11) -> 46276 | B33: =IF(OR(A33<$H$5,A33>$J$5),"",SUMIFS(Datos!$E$5:$E$228,Datos!$A$5:$A$228,A33,Datos!$M$5:$M$228,1)) -> 533 | C33: =IF(B33="","",SUMIFS(Datos!$G$5:$G$228,Datos!$A$5:$A$228,A33,Datos!$M$5:$M$228,1)) -> 35.512 | D33: =IF(OR(B33="",C33=0),"",B33/C33) -> 15.009011 | E33: =IF(COUNTIFS(Datos!$A$5:$A$228,A33,Datos!$M$5:$M$228,1,Datos!$Q$5:$Q$228,">0")=0,"Pendiente GPS",_xlfn.MAXIFS(Datos!$Q$5:$Q$228,Datos!$A$5:$A$228,A33,Datos!$M$5:$M$228,1)) -> Pendiente GPS | F33: =COUNTIFS($A$53:$A$180,A33,$C$53:$C$180,"Volquete",$H$53:$H$180,"Movimiento") -> 4 | G33: =COUNTIFS($A$53:$A$180,A33,$C$53:$C$180,"Volquete",$H$53:$H$180,"Stand by*") -> 0 | H33: =IF(B33="","",SUMIFS(Datos!$H$5:$H$228,Datos!$A$5:$A$228,A33,Datos!$M$5:$M$228,1)) -> 6
A34: =A33+1 -> 46277 | B34: =IF(OR(A34<$H$5,A34>$J$5),"",SUMIFS(Datos!$E$5:$E$228,Datos!$A$5:$A$228,A34,Datos!$M$5:$M$228,1)) -> 536 | C34: =IF(B34="","",SUMIFS(Datos!$G$5:$G$228,Datos!$A$5:$A$228,A34,Datos!$M$5:$M$228,1)) -> 35.817 | D34: =IF(OR(B34="",C34=0),"",B34/C34) -> 14.964961 | E34: =IF(COUNTIFS(Datos!$A$5:$A$228,A34,Datos!$M$5:$M$228,1,Datos!$Q$5:$Q$228,">0")=0,"Pendiente GPS",_xlfn.MAXIFS(Datos!$Q$5:$Q$228,Datos!$A$5:$A$228,A34,Datos!$M$5:$M$228,1)) -> Pendiente GPS | F34: =COUNTIFS($A$53:$A$180,A34,$C$53:$C$180,"Volquete",$H$53:$H$180,"Movimiento") -> 4 | G34: =COUNTIFS($A$53:$A$180,A34,$C$53:$C$180,"Volquete",$H$53:$H$180,"Stand by*") -> 0 | H34: =IF(B34="","",SUMIFS(Datos!$H$5:$H$228,Datos!$A$5:$A$228,A34,Datos!$M$5:$M$228,1)) -> 4
A35: =A34+1 -> 46278 | B35: =IF(OR(A35<$H$5,A35>$J$5),"",SUMIFS(Datos!$E$5:$E$228,Datos!$A$5:$A$228,A35,Datos!$M$5:$M$228,1)) -> 513 | C35: =IF(B35="","",SUMIFS(Datos!$G$5:$G$228,Datos!$A$5:$A$228,A35,Datos!$M$5:$M$228,1)) -> 34.326 | D35: =IF(OR(B35="",C35=0),"",B35/C35) -> 14.94494 | E35: =IF(COUNTIFS(Datos!$A$5:$A$228,A35,Datos!$M$5:$M$228,1,Datos!$Q$5:$Q$228,">0")=0,"Pendiente GPS",_xlfn.MAXIFS(Datos!$Q$5:$Q$228,Datos!$A$5:$A$228,A35,Datos!$M$5:$M$228,1)) -> Pendiente GPS | F35: =COUNTIFS($A$53:$A$180,A35,$C$53:$C$180,"Volquete",$H$53:$H$180,"Movimiento") -> 4 | G35: =COUNTIFS($A$53:$A$180,A35,$C$53:$C$180,"Volquete",$H$53:$H$180,"Stand by*") -> 0 | H35: =IF(B35="","",SUMIFS(Datos!$H$5:$H$228,Datos!$A$5:$A$228,A35,Datos!$M$5:$M$228,1)) -> 6
A36: =A35+1 -> 46279 | B36: =IF(OR(A36<$H$5,A36>$J$5),"",SUMIFS(Datos!$E$5:$E$228,Datos!$A$5:$A$228,A36,Datos!$M$5:$M$228,1)) -> 538 | C36: =IF(B36="","",SUMIFS(Datos!$G$5:$G$228,Datos!$A$5:$A$228,A36,Datos!$M$5:$M$228,1)) -> 35.924 | D36: =IF(OR(B36="",C36=0),"",B36/C36) -> 14.976061 | E36: =IF(COUNTIFS(Datos!$A$5:$A$228,A36,Datos!$M$5:$M$228,1,Datos!$Q$5:$Q$228,">0")=0,"Pendiente GPS",_xlfn.MAXIFS(Datos!$Q$5:$Q$228,Datos!$A$5:$A$228,A36,Datos!$M$5:$M$228,1)) -> Pendiente GPS | F36: =COUNTIFS($A$53:$A$180,A36,$C$53:$C$180,"Volquete",$H$53:$H$180,"Movimiento") -> 4 | G36: =COUNTIFS($A$53:$A$180,A36,$C$53:$C$180,"Volquete",$H$53:$H$180,"Stand by*") -> 0 | H36: =IF(B36="","",SUMIFS(Datos!$H$5:$H$228,Datos!$A$5:$A$228,A36,Datos!$M$5:$M$228,1)) -> 6
A37: =A36+1 -> 46280 | B37: =IF(OR(A37<$H$5,A37>$J$5),"",SUMIFS(Datos!$E$5:$E$228,Datos!$A$5:$A$228,A37,Datos!$M$5:$M$228,1)) -> 536 | C37: =IF(B37="","",SUMIFS(Datos!$G$5:$G$228,Datos!$A$5:$A$228,A37,Datos!$M$5:$M$228,1)) -> 35.726 | D37: =IF(OR(B37="",C37=0),"",B37/C37) -> 15.003079 | E37: =IF(COUNTIFS(Datos!$A$5:$A$228,A37,Datos!$M$5:$M$228,1,Datos!$Q$5:$Q$228,">0")=0,"Pendiente GPS",_xlfn.MAXIFS(Datos!$Q$5:$Q$228,Datos!$A$5:$A$228,A37,Datos!$M$5:$M$228,1)) -> Pendiente GPS | F37: =COUNTIFS($A$53:$A$180,A37,$C$53:$C$180,"Volquete",$H$53:$H$180,"Movimiento") -> 4 | G37: =COUNTIFS($A$53:$A$180,A37,$C$53:$C$180,"Volquete",$H$53:$H$180,"Stand by*") -> 0 | H37: =IF(B37="","",SUMIFS(Datos!$H$5:$H$228,Datos!$A$5:$A$228,A37,Datos!$M$5:$M$228,1)) -> 6
A38: =A37+1 -> 46281 | B38: =IF(OR(A38<$H$5,A38>$J$5),"",SUMIFS(Datos!$E$5:$E$228,Datos!$A$5:$A$228,A38,Datos!$M$5:$M$228,1)) -> 537 | C38: =IF(B38="","",SUMIFS(Datos!$G$5:$G$228,Datos!$A$5:$A$228,A38,Datos!$M$5:$M$228,1)) -> 35.857 | D38: =IF(OR(B38="",C38=0),"",B38/C38) -> 14.976155 | E38: =IF(COUNTIFS(Datos!$A$5:$A$228,A38,Datos!$M$5:$M$228,1,Datos!$Q$5:$Q$228,">0")=0,"Pendiente GPS",_xlfn.MAXIFS(Datos!$Q$5:$Q$228,Datos!$A$5:$A$228,A38,Datos!$M$5:$M$228,1)) -> Pendiente GPS | F38: =COUNTIFS($A$53:$A$180,A38,$C$53:$C$180,"Volquete",$H$53:$H$180,"Movimiento") -> 4 | G38: =COUNTIFS($A$53:$A$180,A38,$C$53:$C$180,"Volquete",$H$53:$H$180,"Stand by*") -> 0 | H38: =IF(B38="","",SUMIFS(Datos!$H$5:$H$228,Datos!$A$5:$A$228,A38,Datos!$M$5:$M$228,1)) -> 4
A39: =A38+1 -> 46282 | B39: =IF(OR(A39<$H$5,A39>$J$5),"",SUMIFS(Datos!$E$5:$E$228,Datos!$A$5:$A$228,A39,Datos!$M$5:$M$228,1)) -> 538 | C39: =IF(B39="","",SUMIFS(Datos!$G$5:$G$228,Datos!$A$5:$A$228,A39,Datos!$M$5:$M$228,1)) -> 36.002 | D39: =IF(OR(B39="",C39=0),"",B39/C39) -> 14.943614 | E39: =IF(COUNTIFS(Datos!$A$5:$A$228,A39,Datos!$M$5:$M$228,1,Datos!$Q$5:$Q$228,">0")=0,"Pendiente GPS",_xlfn.MAXIFS(Datos!$Q$5:$Q$228,Datos!$A$5:$A$228,A39,Datos!$M$5:$M$228,1)) -> Pendiente GPS | F39: =COUNTIFS($A$53:$A$180,A39,$C$53:$C$180,"Volquete",$H$53:$H$180,"Movimiento") -> 4 | G39: =COUNTIFS($A$53:$A$180,A39,$C$53:$C$180,"Volquete",$H$53:$H$180,"Stand by*") -> 0 | H39: =IF(B39="","",SUMIFS(Datos!$H$5:$H$228,Datos!$A$5:$A$228,A39,Datos!$M$5:$M$228,1)) -> 6
A40: =A39+1 -> 46283 | B40: =IF(OR(A40<$H$5,A40>$J$5),"",SUMIFS(Datos!$E$5:$E$228,Datos!$A$5:$A$228,A40,Datos!$M$5:$M$228,1)) -> 517 | C40: =IF(B40="","",SUMIFS(Datos!$G$5:$G$228,Datos!$A$5:$A$228,A40,Datos!$M$5:$M$228,1)) -> 34.421 | D40: =IF(OR(B40="",C40=0),"",B40/C40) -> 15.019901 | E40: =IF(COUNTIFS(Datos!$A$5:$A$228,A40,Datos!$M$5:$M$228,1,Datos!$Q$5:$Q$228,">0")=0,"Pendiente GPS",_xlfn.MAXIFS(Datos!$Q$5:$Q$228,Datos!$A$5:$A$228,A40,Datos!$M$5:$M$228,1)) -> Pendiente GPS | F40: =COUNTIFS($A$53:$A$180,A40,$C$53:$C$180,"Volquete",$H$53:$H$180,"Movimiento") -> 4 | G40: =COUNTIFS($A$53:$A$180,A40,$C$53:$C$180,"Volquete",$H$53:$H$180,"Stand by*") -> 0 | H40: =IF(B40="","",SUMIFS(Datos!$H$5:$H$228,Datos!$A$5:$A$228,A40,Datos!$M$5:$M$228,1)) -> 6
A41: =A40+1 -> 46284 | B41: =IF(OR(A41<$H$5,A41>$J$5),"",SUMIFS(Datos!$E$5:$E$228,Datos!$A$5:$A$228,A41,Datos!$M$5:$M$228,1)) -> 516 | C41: =IF(B41="","",SUMIFS(Datos!$G$5:$G$228,Datos!$A$5:$A$228,A41,Datos!$M$5:$M$228,1)) -> 34.504 | D41: =IF(OR(B41="",C41=0),"",B41/C41) -> 14.954788 | E41: =IF(COUNTIFS(Datos!$A$5:$A$228,A41,Datos!$M$5:$M$228,1,Datos!$Q$5:$Q$228,">0")=0,"Pendiente GPS",_xlfn.MAXIFS(Datos!$Q$5:$Q$228,Datos!$A$5:$A$228,A41,Datos!$M$5:$M$228,1)) -> Pendiente GPS | F41: =COUNTIFS($A$53:$A$180,A41,$C$53:$C$180,"Volquete",$H$53:$H$180,"Movimiento") -> 4 | G41: =COUNTIFS($A$53:$A$180,A41,$C$53:$C$180,"Volquete",$H$53:$H$180,"Stand by*") -> 0 | H41: =IF(B41="","",SUMIFS(Datos!$H$5:$H$228,Datos!$A$5:$A$228,A41,Datos!$M$5:$M$228,1)) -> 6
A42: =A41+1 -> 46285 | B42: =IF(OR(A42<$H$5,A42>$J$5),"",SUMIFS(Datos!$E$5:$E$228,Datos!$A$5:$A$228,A42,Datos!$M$5:$M$228,1)) -> 521 | C42: =IF(B42="","",SUMIFS(Datos!$G$5:$G$228,Datos!$A$5:$A$228,A42,Datos!$M$5:$M$228,1)) -> 34.716 | D42: =IF(OR(B42="",C42=0),"",B42/C42) -> 15.007489 | E42: =IF(COUNTIFS(Datos!$A$5:$A$228,A42,Datos!$M$5:$M$228,1,Datos!$Q$5:$Q$228,">0")=0,"Pendiente GPS",_xlfn.MAXIFS(Datos!$Q$5:$Q$228,Datos!$A$5:$A$228,A42,Datos!$M$5:$M$228,1)) -> Pendiente GPS | F42: =COUNTIFS($A$53:$A$180,A42,$C$53:$C$180,"Volquete",$H$53:$H$180,"Movimiento") -> 4 | G42: =COUNTIFS($A$53:$A$180,A42,$C$53:$C$180,"Volquete",$H$53:$H$180,"Stand by*") -> 0 | H42: =IF(B42="","",SUMIFS(Datos!$H$5:$H$228,Datos!$A$5:$A$228,A42,Datos!$M$5:$M$228,1)) -> 4
A43: =A42+1 -> 46286 | B43: =IF(OR(A43<$H$5,A43>$J$5),"",SUMIFS(Datos!$E$5:$E$228,Datos!$A$5:$A$228,A43,Datos!$M$5:$M$228,1)) -> 542 | C43: =IF(B43="","",SUMIFS(Datos!$G$5:$G$228,Datos!$A$5:$A$228,A43,Datos!$M$5:$M$228,1)) -> 36.207 | D43: =IF(OR(B43="",C43=0),"",B43/C43) -> 14.969481 | E43: =IF(COUNTIFS(Datos!$A$5:$A$228,A43,Datos!$M$5:$M$228,1,Datos!$Q$5:$Q$228,">0")=0,"Pendiente GPS",_xlfn.MAXIFS(Datos!$Q$5:$Q$228,Datos!$A$5:$A$228,A43,Datos!$M$5:$M$228,1)) -> Pendiente GPS | F43: =COUNTIFS($A$53:$A$180,A43,$C$53:$C$180,"Volquete",$H$53:$H$180,"Movimiento") -> 4 | G43: =COUNTIFS($A$53:$A$180,A43,$C$53:$C$180,"Volquete",$H$53:$H$180,"Stand by*") -> 0 | H43: =IF(B43="","",SUMIFS(Datos!$H$5:$H$228,Datos!$A$5:$A$228,A43,Datos!$M$5:$M$228,1)) -> 6
A44: =A43+1 -> 46287 | B44: =IF(OR(A44<$H$5,A44>$J$5),"",SUMIFS(Datos!$E$5:$E$228,Datos!$A$5:$A$228,A44,Datos!$M$5:$M$228,1)) -> 547 | C44: =IF(B44="","",SUMIFS(Datos!$G$5:$G$228,Datos!$A$5:$A$228,A44,Datos!$M$5:$M$228,1)) -> 36.437 | D44: =IF(OR(B44="",C44=0),"",B44/C44) -> 15.012213 | E44: =IF(COUNTIFS(Datos!$A$5:$A$228,A44,Datos!$M$5:$M$228,1,Datos!$Q$5:$Q$228,">0")=0,"Pendiente GPS",_xlfn.MAXIFS(Datos!$Q$5:$Q$228,Datos!$A$5:$A$228,A44,Datos!$M$5:$M$228,1)) -> Pendiente GPS | F44: =COUNTIFS($A$53:$A$180,A44,$C$53:$C$180,"Volquete",$H$53:$H$180,"Movimiento") -> 4 | G44: =COUNTIFS($A$53:$A$180,A44,$C$53:$C$180,"Volquete",$H$53:$H$180,"Stand by*") -> 0 | H44: =IF(B44="","",SUMIFS(Datos!$H$5:$H$228,Datos!$A$5:$A$228,A44,Datos!$M$5:$M$228,1)) -> 6
A45: =A44+1 -> 46288 | B45: =IF(OR(A45<$H$5,A45>$J$5),"",SUMIFS(Datos!$E$5:$E$228,Datos!$A$5:$A$228,A45,Datos!$M$5:$M$228,1)) -> 543 | C45: =IF(B45="","",SUMIFS(Datos!$G$5:$G$228,Datos!$A$5:$A$228,A45,Datos!$M$5:$M$228,1)) -> 36.296 | D45: =IF(OR(B45="",C45=0),"",B45/C45) -> 14.960326 | E45: =IF(COUNTIFS(Datos!$A$5:$A$228,A45,Datos!$M$5:$M$228,1,Datos!$Q$5:$Q$228,">0")=0,"Pendiente GPS",_xlfn.MAXIFS(Datos!$Q$5:$Q$228,Datos!$A$5:$A$228,A45,Datos!$M$5:$M$228,1)) -> Pendiente GPS | F45: =COUNTIFS($A$53:$A$180,A45,$C$53:$C$180,"Volquete",$H$53:$H$180,"Movimiento") -> 4 | G45: =COUNTIFS($A$53:$A$180,A45,$C$53:$C$180,"Volquete",$H$53:$H$180,"Stand by*") -> 0 | H45: =IF(B45="","",SUMIFS(Datos!$H$5:$H$228,Datos!$A$5:$A$228,A45,Datos!$M$5:$M$228,1)) -> 6
... A48: =A47+1 -> 46291 | B48: =IF(OR(A48<$H$5,A48>$J$5),"",SUMIFS(Datos!$E$5:$E$228,Datos!$A$5:$A$228,A48,Datos!$M$5:$M$228,1)) -> 0 | C48: =IF(B48="","",SUMIFS(Datos!$G$5:$G$228,Datos!$A$5:$A$228,A48,Datos!$M$5:$M$228,1)) -> 0 | D48: =IF(OR(B48="",C48=0),"",B48/C48) | E48: =IF(COUNTIFS(Datos!$A$5:$A$228,A48,Datos!$M$5:$M$228,1,Datos!$Q$5:$Q$228,">0")=0,"Pendiente GPS",_xlfn.MAXIFS(Datos!$Q$5:$Q$228,Datos!$A$5:$A$228,A48,Datos!$M$5:$M$228,1)) -> Pendiente GPS | F48: =COUNTIFS($A$53:$A$180,A48,$C$53:$C$180,"Volquete",$H$53:$H$180,"Movimiento") -> 0 | G48: =COUNTIFS($A$53:$A$180,A48,$C$53:$C$180,"Volquete",$H$53:$H$180,"Stand by*") -> 0 | H48: =IF(B48="","",SUMIFS(Datos!$H$5:$H$228,Datos!$A$5:$A$228,A48,Datos!$M$5:$M$228,1)) -> 0
A49: *Stand by diario: hubo horas de motor, pero 0 horas de movimiento en el período filtrado. No representa estado actual.
A50: DETALLE DIARIO POR UNIDAD · 16 FECHAS × 8 UNIDADES
...

Sheet Operaciones
A2: OPERACIONES · CONTROL DE FLOTA
A3: Filtros compartidos con Seguridad
A4: Flota | D4: Turno | G4: Desde | I4: Hasta | L4: Unidad
B5: =Seguridad!B5 -> Volquete | E5: =Seguridad!E5 -> Ambos | H5: =Seguridad!H5 -> 46276 | J5: =Seguridad!J5 -> 46291 | M5: =Seguridad!M5 -> Todas
A8: Distancia recorrida (km) | D8: Horas de motor | G8: Horas en movimiento | J8: Paradas registradas
A9: =SUMIFS(Datos!$E$5:$E$228,Datos!$M$5:$M$228,1) -> 7463 | D9: =SUMIFS(Datos!$F$5:$F$228,Datos!$M$5:$M$228,1) -> 806.2 | G9: =SUMIFS(Datos!$G$5:$G$228,Datos!$M$5:$M$228,1) -> 498.199 | J9: =SUMIFS(Datos!$K$5:$K$228,Datos!$M$5:$M$228,1) -> 451
A12: RESULTADO POR UNIDAD
A14: Unidad | B14: Tipo | C14: km | D14: Motor h | E14: Movimiento h | F14: Paradas | G14: Registros
A15: VOL-01 | B15: Volquete | C15: =IF(G15=0,"",SUMIFS(Datos!$E$5:$E$228,Datos!$B$5:$B$228,A15,Datos!$M$5:$M$228,1)) -> 1876 | D15: =IF(G15=0,"",SUMIFS(Datos!$F$5:$F$228,Datos!$B$5:$B$228,A15,Datos!$M$5:$M$228,1)) -> 201.4 | E15: =IF(G15=0,"",SUMIFS(Datos!$G$5:$G$228,Datos!$B$5:$B$228,A15,Datos!$M$5:$M$228,1)) -> 125.147 | F15: =IF(G15=0,"",SUMIFS(Datos!$K$5:$K$228,Datos!$B$5:$B$228,A15,Datos!$M$5:$M$228,1)) -> 115 | G15: =COUNTIFS(Datos!$B$5:$B$228,A15,Datos!$M$5:$M$228,1) -> 28
A16: VOL-02 | B16: Volquete | C16: =IF(G16=0,"",SUMIFS(Datos!$E$5:$E$228,Datos!$B$5:$B$228,A16,Datos!$M$5:$M$228,1)) -> 1827 | D16: =IF(G16=0,"",SUMIFS(Datos!$F$5:$F$228,Datos!$B$5:$B$228,A16,Datos!$M$5:$M$228,1)) -> 199 | E16: =IF(G16=0,"",SUMIFS(Datos!$G$5:$G$228,Datos!$B$5:$B$228,A16,Datos!$M$5:$M$228,1)) -> 121.937 | F16: =IF(G16=0,"",SUMIFS(Datos!$K$5:$K$228,Datos!$B$5:$B$228,A16,Datos!$M$5:$M$228,1)) -> 111 | G16: =COUNTIFS(Datos!$B$5:$B$228,A16,Datos!$M$5:$M$228,1) -> 28
A17: VOL-03 | B17: Volquete | C17: =IF(G17=0,"",SUMIFS(Datos!$E$5:$E$228,Datos!$B$5:$B$228,A17,Datos!$M$5:$M$228,1)) -> 1870 | D17: =IF(G17=0,"",SUMIFS(Datos!$F$5:$F$228,Datos!$B$5:$B$228,A17,Datos!$M$5:$M$228,1)) -> 201.6 | E17: =IF(G17=0,"",SUMIFS(Datos!$G$5:$G$228,Datos!$B$5:$B$228,A17,Datos!$M$5:$M$228,1)) -> 124.906 | F17: =IF(G17=0,"",SUMIFS(Datos!$K$5:$K$228,Datos!$B$5:$B$228,A17,Datos!$M$5:$M$228,1)) -> 112 | G17: =COUNTIFS(Datos!$B$5:$B$228,A17,Datos!$M$5:$M$228,1) -> 28
A18: VOL-04 | B18: Volquete | C18: =IF(G18=0,"",SUMIFS(Datos!$E$5:$E$228,Datos!$B$5:$B$228,A18,Datos!$M$5:$M$228,1)) -> 1890 | D18: =IF(G18=0,"",SUMIFS(Datos!$F$5:$F$228,Datos!$B$5:$B$228,A18,Datos!$M$5:$M$228,1)) -> 204.2 | E18: =IF(G18=0,"",SUMIFS(Datos!$G$5:$G$228,Datos!$B$5:$B$228,A18,Datos!$M$5:$M$228,1)) -> 126.209 | F18: =IF(G18=0,"",SUMIFS(Datos!$K$5:$K$228,Datos!$B$5:$B$228,A18,Datos!$M$5:$M$228,1)) -> 113 | G18: =COUNTIFS(Datos!$B$5:$B$228,A18,Datos!$M$5:$M$228,1) -> 28
A19: CAM-01 | B19: Camioneta | C19: =IF(G19=0,"",SUMIFS(Datos!$E$5:$E$228,Datos!$B$5:$B$228,A19,Datos!$M$5:$M$228,1)) | D19: =IF(G19=0,"",SUMIFS(Datos!$F$5:$F$228,Datos!$B$5:$B$228,A19,Datos!$M$5:$M$228,1)) | E19: =IF(G19=0,"",SUMIFS(Datos!$G$5:$G$228,Datos!$B$5:$B$228,A19,Datos!$M$5:$M$228,1)) | F19: =IF(G19=0,"",SUMIFS(Datos!$K$5:$K$228,Datos!$B$5:$B$228,A19,Datos!$M$5:$M$228,1)) | G19: =COUNTIFS(Datos!$B$5:$B$228,A19,Datos!$M$5:$M$228,1) -> 0
A20: CAM-02 | B20: Camioneta | C20: =IF(G20=0,"",SUMIFS(Datos!$E$5:$E$228,Datos!$B$5:$B$228,A20,Datos!$M$5:$M$228,1)) | D20: =IF(G20=0,"",SUMIFS(Datos!$F$5:$F$228,Datos!$B$5:$B$228,A20,Datos!$M$5:$M$228,1)) | E20: =IF(G20=0,"",SUMIFS(Datos!$G$5:$G$228,Datos!$B$5:$B$228,A20,Datos!$M$5:$M$228,1)) | F20: =IF(G20=0,"",SUMIFS(Datos!$K$5:$K$228,Datos!$B$5:$B$228,A20,Datos!$M$5:$M$228,1)) | G20: =COUNTIFS(Datos!$B$5:$B$228,A20,Datos!$M$5:$M$228,1) -> 0
A21: MIN-01 | B21: Minibús | C21: =IF(G21=0,"",SUMIFS(Datos!$E$5:$E$228,Datos!$B$5:$B$228,A21,Datos!$M$5:$M$228,1)) | D21: =IF(G21=0,"",SUMIFS(Datos!$F$5:$F$228,Datos!$B$5:$B$228,A21,Datos!$M$5:$M$228,1)) | E21: =IF(G21=0,"",SUMIFS(Datos!$G$5:$G$228,Datos!$B$5:$B$228,A21,Datos!$M$5:$M$228,1)) | F21: =IF(G21=0,"",SUMIFS(Datos!$K$5:$K$228,Datos!$B$5:$B$228,A21,Datos!$M$5:$M$228,1)) | G21: =COUNTIFS(Datos!$B$5:$B$228,A21,Datos!$M$5:$M$228,1) -> 0
A22: COM-01 | B22: Combi | C22: =IF(G22=0,"",SUMIFS(Datos!$E$5:$E$228,Datos!$B$5:$B$228,A22,Datos!$M$5:$M$228,1)) | D22: =IF(G22=0,"",SUMIFS(Datos!$F$5:$F$228,Datos!$B$5:$B$228,A22,Datos!$M$5:$M$228,1)) | E22: =IF(G22=0,"",SUMIFS(Datos!$G$5:$G$228,Datos!$B$5:$B$228,A22,Datos!$M$5:$M$228,1)) | F22: =IF(G22=0,"",SUMIFS(Datos!$K$5:$K$228,Datos!$B$5:$B$228,A22,Datos!$M$5:$M$228,1)) | G22: =COUNTIFS(Datos!$B$5:$B$228,A22,Datos!$M$5:$M$228,1) -> 0

Sheet Datos
A1: DATOS PILOTO · una fila por unidad, fecha y turno. Sustituir por exportación real para uso operativo.
A4: Fecha | B4: Unidad | C4: Tipo | D4: Turno | E4: Distancia km | F4: Motor h | G4: Movimiento h | H4: Eventos sobrevelocidad | I4: Alertas cinturón | J4: Salidas geocerca | K4: Paradas | L4: Desconexiones | M4: Incluido por filtros | O4: Definiciones | Q4: Velocidad máxima GPS (km/h)
A5: 46276 | B5: VOL-01 | C5: Volquete | D5: Día | E5: 64 | F5: 6.2 | G5: 4.278 | H5: 2 | I5: 0 | J5: 0 | K5: 4 | L5: 0 | M5: =IF(AND(A5>=Seguridad!$H$5,A5<=Seguridad!$J$5,OR(Seguridad!$B$5="Todas",C5=Seguridad!$B$5),OR(Seguridad!$E$5="Ambos",D5=Seguridad!$E$5),OR(Seguridad!$M$5="Todas",B5=Seguridad!$M$5)),1,0) -> 1 | O5: Velocidad media diaria | P5: Suma de km ÷ suma de horas de movimiento de los turnos filtrados.
A6: 46276 | B6: VOL-01 | C6: Volquete | D6: Noche | E6: 66 | F6: 7.3 | G6: 4.38 | H6: 1 | I6: 0 | J6: 0 | K6: 5 | L6: 0 | M6: =IF(AND(A6>=Seguridad!$H$5,A6<=Seguridad!$J$5,OR(Seguridad!$B$5="Todas",C6=Seguridad!$B$5),OR(Seguridad!$E$5="Ambos",D6=Seguridad!$E$5),OR(Seguridad!$M$5="Todas",B6=Seguridad!$M$5)),1,0) -> 1 | O6: Velocidad máxima | P6: Máxima lectura GPS informada en Q por unidad y turno. Vacío = pendiente.
A7: 46277 | B7: VOL-01 | C7: Volquete | D7: Día | E7: 58 | F7: 6.9 | G7: 3.864 | H7: 2 | I7: 0 | J7: 0 | K7: 6 | L7: 0 | M7: =IF(AND(A7>=Seguridad!$H$5,A7<=Seguridad!$J$5,OR(Seguridad!$B$5="Todas",C7=Seguridad!$B$5),OR(Seguridad!$E$5="Ambos",D7=Seguridad!$E$5),OR(Seguridad!$M$5="Todas",B7=Seguridad!$M$5)),1,0) -> 1 | O7: Estado en vivo | P7: Requiere muestras externas con hora, motor y velocidad en Telemetría.
A8: 46277 | B8: VOL-01 | C8: Volquete | D8: Noche | E8: 80 | F8: 8 | G8: 5.36 | H8: 0 | I8: 0 | J8: 1 | K8: 2 | L8: 0 | M8: =IF(AND(A8>=Seguridad!$H$5,A8<=Seguridad!$J$5,OR(Seguridad!$B$5="Todas",C8=Seguridad!$B$5),OR(Seguridad!$E$5="Ambos",D8=Seguridad!$E$5),OR(Seguridad!$M$5="Todas",B8=Seguridad!$M$5)),1,0) -> 1
A9: 46278 | B9: VOL-01 | C9: Volquete | D9: Día | E9: 72 | F9: 7.6 | G9: 4.788 | H9: 2 | I9: 1 | J9: 0 | K9: 3 | L9: 0 | M9: =IF(AND(A9>=Seguridad!$H$5,A9<=Seguridad!$J$5,OR(Seguridad!$B$5="Todas",C9=Seguridad!$B$5),OR(Seguridad!$E$5="Ambos",D9=Seguridad!$E$5),OR(Seguridad!$M$5="Todas",B9=Seguridad!$M$5)),1,0) -> 1
A10: 46278 | B10: VOL-01 | C10: Volquete | D10: Noche | E10: 50 | F10: 6.2 | G10: 3.348 | H10: 0 | I10: 0 | J10: 0 | K10: 4 | L10: 0 | M10: =IF(AND(A10>=Seguridad!$H$5,A10<=Seguridad!$J$5,OR(Seguridad!$B$5="Todas",C10=Seguridad!$B$5),OR(Seguridad!$E$5="Ambos",D10=Seguridad!$E$5),OR(Seguridad!$M$5="Todas",B10=Seguridad!$M$5)),1,0) -> 1
A11: 46279 | B11: VOL-01 | C11: Volquete | D11: Día | E11: 87 | F11: 8.3 | G11: 5.81 | H11: 2 | I11: 0 | J11: 0 | K11: 5 | L11: 0 | M11: =IF(AND(A11>=Seguridad!$H$5,A11<=Seguridad!$J$5,OR(Seguridad!$B$5="Todas",C11=Seguridad!$B$5),OR(Seguridad!$E$5="Ambos",D11=Seguridad!$E$5),OR(Seguridad!$M$5="Todas",B11=Seguridad!$M$5)),1,0) -> 1
A12: 46279 | B12: VOL-01 | C12: Volquete | D12: Noche | E12: 63 | F12: 6.9 | G12: 4.209 | H12: 0 | I12: 0 | J12: 0 | K12: 6 | L12: 0 | M12: =IF(AND(A12>=Seguridad!$H$5,A12<=Seguridad!$J$5,OR(Seguridad!$B$5="Todas",C12=Seguridad!$B$5),OR(Seguridad!$E$5="Ambos",D12=Seguridad!$E$5),OR(Seguridad!$M$5="Todas",B12=Seguridad!$M$5)),1,0) -> 1
A13: 46280 | B13: VOL-01 | C13: Volquete | D13: Día | E13: 56 | F13: 6.5 | G13: 3.705 | H13: 2 | I13: 0 | J13: 0 | K13: 2 | L13: 0 | M13: =IF(AND(A13>=Seguridad!$H$5,A13<=Seguridad!$J$5,OR(Seguridad!$B$5="Todas",C13=Seguridad!$B$5),OR(Seguridad!$E$5="Ambos",D13=Seguridad!$E$5),OR(Seguridad!$M$5="Todas",B13=Seguridad!$M$5)),1,0) -> 1
A14: 46280 | B14: VOL-01 | C14: Volquete | D14: Noche | E14: 78 | F14: 7.6 | G14: 5.168 | H14: 1 | I14: 0 | J14: 0 | K14: 3 | L14: 0 | M14: =IF(AND(A14>=Seguridad!$H$5,A14<=Seguridad!$J$5,OR(Seguridad!$B$5="Todas",C14=Seguridad!$B$5),OR(Seguridad!$E$5="Ambos",D14=Seguridad!$E$5),OR(Seguridad!$M$5="Todas",B14=Seguridad!$M$5)),1,0) -> 1
A15: 46281 | B15: VOL-01 | C15: Volquete | D15: Día | E15: 69 | F15: 7.2 | G15: 4.608 | H15: 2 | I15: 0 | J15: 0 | K15: 4 | L15: 0 | M15: =IF(AND(A15>=Seguridad!$H$5,A15<=Seguridad!$J$5,OR(Seguridad!$B$5="Todas",C15=Seguridad!$B$5),OR(Seguridad!$E$5="Ambos",D15=Seguridad!$E$5),OR(Seguridad!$M$5="Todas",B15=Seguridad!$M$5)),1,0) -> 1
A16: 46281 | B16: VOL-01 | C16: Volquete | D16: Noche | E16: 68 | F16: 8.3 | G16: 4.565 | H16: 0 | I16: 0 | J16: 0 | K16: 5 | L16: 0 | M16: =IF(AND(A16>=Seguridad!$H$5,A16<=Seguridad!$J$5,OR(Seguridad!$B$5="Todas",C16=Seguridad!$B$5),OR(Seguridad!$E$5="Ambos",D16=Seguridad!$E$5),OR(Seguridad!$M$5="Todas",B16=Seguridad!$M$5)),1,0) -> 1
A17: 46282 | B17: VOL-01 | C17: Volquete | D17: Día | E17: 84 | F17: 7.9 | G17: 5.609 | H17: 2 | I17: 0 | J17: 0 | K17: 6 | L17: 0 | M17: =IF(AND(A17>=Seguridad!$H$5,A17<=Seguridad!$J$5,OR(Seguridad!$B$5="Todas",C17=Seguridad!$B$5),OR(Seguridad!$E$5="Ambos",D17=Seguridad!$E$5),OR(Seguridad!$M$5="Todas",B17=Seguridad!$M$5)),1,0) -> 1
A18: 46282 | B18: VOL-01 | C18: Volquete | D18: Noche | E18: 60 | F18: 6.5 | G18: 4.03 | H18: 0 | I18: 1 | J18: 0 | K18: 2 | L18: 0 | M18: =IF(AND(A18>=Seguridad!$H$5,A18<=Seguridad!$J$5,OR(Seguridad!$B$5="Todas",C18=Seguridad!$B$5),OR(Seguridad!$E$5="Ambos",D18=Seguridad!$E$5),OR(Seguridad!$M$5="Todas",B18=Seguridad!$M$5)),1,0) -> 1
A19: 46283 | B19: VOL-01 | C19: Volquete | D19: Día | E19: 53 | F19: 6.1 | G19: 3.538 | H19: 2 | I19: 0 | J19: 0 | K19: 3 | L19: 0 | M19: =IF(AND(A19>=Seguridad!$H$5,A19<=Seguridad!$J$5,OR(Seguridad!$B$5="Todas",C19=Seguridad!$B$5),OR(Seguridad!$E$5="Ambos",D19=Seguridad!$E$5),OR(Seguridad!$M$5="Todas",B19=Seguridad!$M$5)),1,0) -> 1
... A228: 46289 | B228: COM-01 | C228: Combi | D228: Noche | E228: 168 | F228: 8.3 | G228: 5.81 | H228: 0 | I228: 0 | J228: 0 | K228: 5 | L228: 0 | M228: =IF(AND(A228>=Seguridad!$H$5,A228<=Seguridad!$J$5,OR(Seguridad!$B$5="Todas",C228=Seguridad!$B$5),OR(Seguridad!$E$5="Ambos",D228=Seguridad!$E$5),OR(Seguridad!$M$5="Todas",B228=Seguridad!$M$5)),1,0) -> 0

Sheet Telemetría
A1: ENTRADA DE TELEMETRÍA · pegar muestras reales, una fila por unidad y hora. Se actualiza al refrescar/importar la fuente.
A2: Hora local del equipo (fecha y hora) | velocidad GPS en km/h | motor: 1 encendido, 0 apagado | turno: Día/Noche
A4: Fecha y hora | B4: Unidad | C4: Tipo | D4: Turno | E4: Velocidad GPS km/h | F4: Motor (1/0) | G4: Fuente / observación
